Workbook
Name A: #REF!
Name A: #REF!
Name AAAAAAZ: #REF!
Name AAAAAAZ: #REF!
Name AB: #REF!
Name AB: #REF!
Name Activité_14: [1]Processus!#REF!
Name Activité_14: [1]Processus!#REF!
Name AD: #REF!
Name AD: #REF!
Name Admin: '[2]Range Page'!$A$21
Name adminfee: '[3]Range Page'!$A$24
Name agent: #REF!
Name agent: #REF!
Name anjakakk\: #REF!
Name anjakakk\: #REF!
Name AOUT: #REF!
Name AOUT: #REF!
Name Août: #REF!
Name Août: #REF!
Name aqs: #REF!
Name aqs: #REF!
Name Avril: #REF!
Name Avril: #REF!
Name az: #REF!
Name az: #REF!
Name AZERTY: #REF!
Name AZERTY: #REF!
Name BHGFR: #REF!
Name BHGFR: #REF!
Name codprod: [4]Listes!$J$2:$P$44
Name Cost_Category: [5]Definitions!$F$3:$F$15
Name Cost_Category2: [6]Definitions!$F$3:$F$15
Name CSB: [7]liste!$B$2:$F$17
Name CSB: [7]liste!$B$2:$F$17
Name csb: [8]liste!$B$2:$F$17
Name DA: #REF!
Name DA: #REF!
Name dangerpay: '[3]Range Page'!$A$14
Name DECA: #REF!
Name DECA: #REF!
Name Décembre: #REF!
Name Décembre: #REF!
Name Disease_components: [3]Definitions!$A$2:$D$2
Name dist: '[9]Variables-Normes'!#REF!
Name DISTRICT: '[9]Variables-Normes'!#REF!
Name DISTRICTS_FORM: DISTANCES_DISTRICTS!$D$2:$D$116
Name DISTRICTS_FORM: [10]DISTANCES_DISTRICTS!$D$2:$D$116
Name DollarLC: '[3]Range Page'!$A$29
Name DRS: #REF!
Name DRS: #REF!
Name e: #REF!
Name e: #REF!
Name eduallowance.expat1: '[3]Range Page'!$A$15
Name eduallowance.expat2: '[3]Range Page'!$A$16
Name effets: [4]Listes!$F$2:$H$19
Name entree: [11]mouvement!$E$3:$E$65536
Name Excel_BuiltIn__FilterDatabase_2: "$'1_ Variables_Normes'.$#REF !$#REF !:$#REF !$#REF !"
Name Excel_BuiltIn_Print_Area_1: #REF!
Name Excel_BuiltIn_Print_Area_1: #REF!

Sheet PARAMETRES
A1: PARAMETRES – RÉFÉRENCE UNIQUE DES RÈGLES
A2: Les listes de choix sont exclusivement dans LISTES. PARAMETRES contient uniquement les règles, taux, seuils et matrice des PJ.
A4: 1. INDEMNITÉS | B4: TAUX | D4: 3. DÉPLACEMENT / TRANSFERT | G4: 5. RÈGLES DE RAPPORTAGE
A5: Taux Perdiem chef-lieu région | B5: 200000 | D5: Transfert aéroport International | E5: 500000 | G5: UNICEF – seuil attention (jours) | H5: 90
A6: Taux Perdiem chef-lieu district | B6: 150000 | D6: Transfert aéroport – Antananarivo | E6: 150000 | G6: UNICEF – seuil bloqué (jours) | H6: 180
A7: Taux Perdiem AC | B7: 60000 | D7: Transfert aéroport – Chef-lieu région | E7: 50000 | G7: Autres bailleurs – seuil attention (jours) | H7: 15
A8: Déjeuner pris en charge | B8: OUI/NON | D8: Transfert aéroport – Chef-lieu district | E8: 50000 | G8: Autres bailleurs – seuil bloqué (jours) | H8: 30
A9: Taux Pernoctem: si mission sans passer la nuit, plus de 8h, NON Déjeuner (60%) | B9: 0.6
A10: Taux Perdiem si NON déjeuner ; DELAI DE ROUTE= 100% | B10: 1 | D10: 4. DÉPLACEMENT FORFAITAIRE | G10: Statut | H10: Interprétation
A11: Taux indemnité avec prise en charge déjeuner(taux Déduit de 15% pour déjeuner) | B11: 0.85 | D11: Déplacement forfaitaire – Antananarivo | E11: 50000 | G11: OK | H11: Rapportage reçu ou délai non atteint
A12: Taux indemnité chauffeur(Toujours taux sans déjeuner= 100% soit de 200 000 ar soit 100% de 150 000 ar) | B12: 1 | D12: Déplacement forfaitaire – Chef-lieu région | E12: 30000 | G12: EN ATTENTE | H12: À relancer
D13: Déplacement forfaitaire – Autres district | E13: 20000 | G13: LIMITE | H13: Seuil d’attention dépassé
A14: 2. CARBURANT | B14: Consommation/km par type de vehicule | G14: BLOQUÉ | H14: Seuil bloqué dépassé
A15: Moto | B15: 0.05
A16: Petite voiture | B16: 0.1 | G16: 6. SOURCE DE FINANCEMENT
A17: Voiture administrative ou 4*4 | B17: 0.15 | G17: UNICEF
A18: Car 16 places | B18: 0.17 | G18: UNFPA
A19: Car plus de 22 places | B19: 0.17 | G19: WISH2
A20: Camion | B20: 0.25 | G20: UPNNC
D21: DOSSIER EXPORT / TÉLÉCHARGEMENT | E21: À définir par ADMIN dans la version .xlsm | G21: AUTRES
A23: 5. MATRICE DES PJ REQUISES ET RÈGLES DE DATE POUR CONTRÔLE DE PJ
A24: RUBRIQUE | B24: SOUS-RUBRIQUE | C24: PJ REQUISE | D24: OBLIGATOIRE | E24: RÈGLE DE DATE | F24: TYPE DE CONTRÔLE | G24: REMARQUE | H24: ACTIF
A25: RESTAURATION | C25: DEMANDE DE COTATION | D25: OUI | E25: Avant activité | F25: DATE | H25: OUI
A26: RESTAURATION | C26: FACTURE PROFORMA | D26: OUI | E26: Avant activité;Après date de demande de cotation | F26: DATE | H26: OUI
A27: RESTAURATION | C27: PV DE SELECTION DES PRESTATAIRES | D27: OUI | E27: Après date demande de cotation;Avant date activité | F27: DATE | H27: OUI
A28: RESTAURATION | C28: BON DE COMMANDE | D28: OUI | E28: Après date PV;Avant activité | F28: DATE | H28: OUI
A29: RESTAURATION | C29: FACTURE DEFINITIVE | D29: OUI | E29: Après activité | F29: DATE | H29: OUI
A30: RESTAURATION | C30: BON DE LIVRAISON | D30: OUI | E30: Après activité | F30: DATE | H30: OUI
A31: RESTAURATION | C31: PV DE RECEPTION DEFINITIVE | D31: OUI | E31: Après activité | F31: DATE | H31: OUI
A32: RESTAURATION | C32: PREUVE DE PAIEMENT | D32: OUI | E32: Après activité | F32: DATE | H32: OUI
A33: RESTAURATION | C33: FICHE DE PRESENCE | D33: OUI | E33: Pendant activité | F33: DATE | H33: OUI
A34: FOURNITURE | C34: DEMANDE DE COTATION | D34: OUI | E34: Avant activité | F34: DATE | H34: OUI
A35: FOURNITURE | C35: FACTURE PROFORMA | D35: OUI | E35: Avant activité;Après date de demande de cotation | F35: DATE | H35: OUI
A36: FOURNITURE | C36: PV DE SELECTION DES PRESTATAIRES | D36: OUI | E36: Après date demande de cotation;Avant date activité | F36: DATE | H36: OUI
... A68: MULTIPLICATION DE DOCUMENT/VISUEL | C68: PREUVE DE PAIEMENT | D68: OUI | E68: Après activité | F68: DATE | H68: OUI
A69: INDEMNITE | B69: INDEMNITE DES MISSIONNAIRES (DELAI DE ROUTE) | C69: ORDRE DE MISSION | D69: OUI | E69: Avant activité | F69: DATE | H69: OUI
A70: INDEMNITE | B70: INDEMNITE DES MISSIONNAIRES (DELAI DE ROUTE) | C70: FICHE DE PRESENCE | D70: OUI | E70: Pendant activité | F70: DATE | H70: OUI
A71: INDEMNITE | B71: INDEMNITE DES MISSIONNAIRES (DELAI DE ROUTE) | C71: ETAT DE PAIEMENT | D71: OUI | E71: Après activité | F71: DATE | H71: OUI
A72: INDEMNITE | B72: INDEMNITE DES MISSIONNAIRES (PENDANT ACTIVITE) | C72: ORDRE DE MISSION | D72: OUI | E72: Avant activité | F72: DATE | H72: OUI
A73: INDEMNITE | B73: INDEMNITE DES MISSIONNAIRES (PENDANT ACTIVITE) | C73: FICHE DE PRESENCE | D73: OUI | E73: Pendant activité | F73: DATE | H73: OUI
...

Sheet ACCUEIL
B2: GESTION & SUIVI UNICEF
B4: Interface de gestion • Budget • Fonds • Dépenses/PJ • Rapport financier • Banque • Rapprochement
B6: 📋 BUDGET | E6: 💰 BUDGET ACCORDÉ | G6: 💵 FONDS / ACTIVITÉS
B10: 🧾 DÉPENSES / PJ | E10: ✓ CONTRÔLE PJ | G10: 📑 RAPPORT FINANCIER
B14: 🏦 JOURNAL DE BANQUE | E14: 🔄 RAPPROCHEMENT | G14: 📊 TABLEAU DE BORD
B18: ⚙ PARAMÈTRES | E18: 📍 DISTANCES | G18: 🗂 LISTES
B22: ADMINISTRATEUR : PARAMETRES • DISTANCES • LISTES • LISTE_ACTIVITES restent accessibles pour contrôle et mise à jour.

Sheet BUDGET
A1: GÉNÉRATEUR AUTOMATIQUE DE BUDGET / PTA
B3: Type activité | C3: FORMATION
B4: Code activité
B5: Description
B6: Date début
B7: Date fin
B8: Nombre de jours
B9: Nombre participants
B10: Nombre missionnaires
B11: Lieu
B12: Zone indemnité
B13: Distance aller (km)
B14: Restauration
B18: RUBRIQUE | C18: unite | D18: nbre de personnes | E18: nbre de jours | F18: TAUX INDEMNITE | G18: Montant (Ar)
A19: 1 | B19: INDEMNITÉS DES MISSIONNAIRES
A20: A | B20: Delai de route | C20: personne | D20: 21 | E20: =+DISTANCES_DISTRICTS!J4 -> 2 | F20: =+REFERENTIEL_TARIFS!F2 -> 200000 | G20: =+D20*E20*F20 -> 8400000 | H20: à revoir referentiel tarif
A21: A-1 | B21: Indeminté des équipes centraux | C21: personne
A22: A-1 | B22: Indeminté des équipes regionaux | C22: personne
B23: Indemnité Chauffeur | C23: personne | D23: 1 | E23: =+E20+E27 -> 4 | F23: =+F20 -> 200000 | H23: Toujours taux complet 100% pour chauffeur
F24: SOUS TOTAUX DELAI DE ROUTE | G24: =+SUM(G20:G23) -> 8400000
A25: B | B25: PENDANT ATELIER | C25: personne
B26: Indeminté des équipes centraux | C26: personne | D26: 21 | E26: =+E19 -> 0 | F26: =+F20-(F20*15%) -> 170000 | G26: =+D26*E26*F26 -> 0 | H26: Si dejeuner est pris en charge pendant atelier
B27: Indeminté des équipes regionaux | C27: personne | D27: 21 | E27: =+E20 -> 2 | F27: =+F20 -> 200000 | G27: =+D27*E27*F27 -> 8400000 | H27: Si dejeuner n'est pris en charge pendant atelier(100%)
F28: SOUS TOTAUX PENDANT ACTIVITE | G28: =SUM(G26:G27) -> 8400000
B29: TOTAL INDEMNITE DES MISSIONNAIRES | G29: =+G28+G24 -> 16800000
A30: 2 | B30: DÉPLACEMENTS DES MISSIONNAIRES | C30: unite | D30: nbre de personnes | E30: nbre de jours | F30: TAUX | G30: Montant (Ar)
A31: A | B31: deplacement forfaitaire
F32: =+REFERENTIEL_TARIFS!F6 -> 50000 | H32: à revoir referentiel tarif
F33: =+REFERENTIEL_TARIFS!F7 -> 30000 | H33: à revoir referentiel tarif
F34: =+REFERENTIEL_TARIFS!F8 -> 20000 | H34: à revoir referentiel tarif
F35: SOUS TOTAUX | G35: =SUM(G32:G34) -> 0
A36: B | B36: CARBURANT | C36: Distance | D36: consommation | E36: Nbre de voiture | F36: PU En ariary | G36: Montant (Ar)
B37: Si Trajet Antananarivo vers Antananarivo Atsimondrano | C37: =+DISTANCES_DISTRICTS!G8 -> 20 | D37: 0.15 | E37: 1 | F37: 4860 | G37: =+C37*D37*E37*F37 -> 14580
F38: SOUS TOTAUX | G38: =+G37 -> 14580
A39: C | B39: LOCATION VÉHICULE | C39: unite | D39: nbre de VOITURE | E39: nbre de jours | F39: PU En ariary | G39: Montant (Ar)
B40: Location de voiture | D40: 2 | E40: 3 | F40: 350000 | G40: =+C40*D40*E40*F40 -> 0
F41: SOUS TOTAUX | G41: =+G40 -> 0
B42: TOTAL DEPLACEMENT DES MISSIONNAIRES | G42: =+G41+G38+G35 -> 14580
A43: 3 | B43: RESTAURATION / ORGANISATION | C43: Fréquence | D43: QUANTITE | E43: nbre de jours | F43: PU En ariary | G43: Montant (Ar)
B44: Eau minérale | C44: 1 | G44: =+C44*D44*E44*F44 -> 0
...

Sheet DISTANCES_DISTRICTS
A1: N° | B1: CHEF-LIEU DE RÉGION | C1: REGION | D1: DISTRICT | E1: EST CHEF-LIEU RÉGION | F1: DISTANCE TANA ALLER (km)CARBURANT | G1: DISTANCE TANA ALLER (km)CARBURANT | H1: DÉLAI ROUTE ALLER | I1: DÉLAI ROUTE RETOUR | J1: DÉLAI ROUTE ALLER ET RETOUR | M1: ↩ RETOUR AU MENU
A2: 7 | B2: Antananarivo-Renivohitra | C2: ANALAMANGA | D2: Antananarivo-Renivohitra | E2: =IF(D2="","",IF(UPPER(D2)=UPPER(B2),"OUI","NON")) -> OUI | F2: 10 | G2: =+F2*2 -> 20 | H2: 0 | I2: 0 | J2: =+H2+I2 -> 0
A3: 1 | B3: Antananarivo-Renivohitra | C3: ANALAMANGA | D3: Ambohidratrimo | E3: =IF(D3="","",IF(UPPER(D3)=UPPER(B3),"OUI","NON")) -> NON | F3: 15 | G3: =+$F$2*2 -> 20 | H3: 0 | I3: 0 | J3: =+H3+I3 -> 0
A4: 2 | B4: Antananarivo-Renivohitra | C4: ANALAMANGA | D4: Andramasina | E4: =IF(D4="","",IF(UPPER(D4)=UPPER(B4),"OUI","NON")) -> NON | F4: 43 | G4: =+$F$2*2 -> 20 | H4: 1 | I4: 1 | J4: =+H4+I4 -> 2
A5: 3 | B5: Antananarivo-Renivohitra | C5: ANALAMANGA | D5: Anjozorobe | E5: =IF(D5="","",IF(UPPER(D5)=UPPER(B5),"OUI","NON")) -> NON | F5: 96 | G5: =+$F$2*2 -> 20 | H5: 1 | I5: 1 | J5: =+H5+I5 -> 2
A6: 4 | B6: Antananarivo-Renivohitra | C6: ANALAMANGA | D6: Ankazobe | E6: =IF(D6="","",IF(UPPER(D6)=UPPER(B6),"OUI","NON")) -> NON | F6: 96 | G6: =+$F$2*2 -> 20 | H6: 1 | I6: 1 | J6: =+H6+I6 -> 2
A7: 5 | B7: Antananarivo-Renivohitra | C7: ANALAMANGA | D7: Antananarivo-Atsimondrano | E7: =IF(D7="","",IF(UPPER(D7)=UPPER(B7),"OUI","NON")) -> NON | F7: 15 | G7: =+$F$2*2 -> 20 | H7: 0 | I7: 0 | J7: =+H7+I7 -> 0
A8: 6 | B8: Antananarivo-Renivohitra | C8: ANALAMANGA | D8: Antananarivo-Avaradrano | E8: =IF(D8="","",IF(UPPER(D8)=UPPER(B8),"OUI","NON")) -> NON | F8: 15 | G8: =+$F$2*2 -> 20 | H8: 0 | I8: 0 | J8: =+H8+I8 -> 0
A9: 8 | B9: Antananarivo-Renivohitra | C9: ANALAMANGA | D9: Manjakandriana | E9: =IF(D9="","",IF(UPPER(D9)=UPPER(B9),"OUI","NON")) -> NON | F9: 45 | G9: =+$F$2*2 -> 20 | H9: 1 | I9: 0 | J9: =+H9+I9 -> 1
A10: 10 | B10: Tsiroanomandidy | C10: BONGOLAVA | D10: Tsiroanomandidy | E10: =IF(D10="","",IF(UPPER(D10)=UPPER(B10),"OUI","NON")) -> OUI | F10: 250 | G10: =+$F$2*2 -> 20 | H10: 1 | I10: 1 | J10: =+H10+I10 -> 2
A11: 9 | B11: Tsiroanomandidy | C11: BONGOLAVA | D11: Fenoarivobe | E11: =IF(D11="","",IF(UPPER(D11)=UPPER(B11),"OUI","NON")) -> NON | F11: 370 | G11: =+$F$2*2 -> 20 | H11: 1 | I11: 1 | J11: =+H11+I11 -> 2
A12: 12 | B12: Miarinarivo | C12: ITASY | D12: Miarinarivo | E12: =IF(D12="","",IF(UPPER(D12)=UPPER(B12),"OUI","NON")) -> OUI | F12: 100 | G12: =+$F$2*2 -> 20 | H12: 1 | I12: 0 | J12: =+H12+I12 -> 1
A13: 11 | B13: Miarinarivo | C13: ITASY | D13: Arivonimamo | E13: =IF(D13="","",IF(UPPER(D13)=UPPER(B13),"OUI","NON")) -> NON | F13: 45 | G13: =+$F$2*2 -> 20 | H13: 1 | I13: 0 | J13: =+H13+I13 -> 1
A14: 13 | B14: Miarinarivo | C14: ITASY | D14: Soavinandriana | E14: =IF(D14="","",IF(UPPER(D14)=UPPER(B14),"OUI","NON")) -> NON | F14: 160 | G14: =+$F$2*2 -> 20 | H14: 1 | I14: 0 | J14: =+H14+I14 -> 1
... A16: 17 | B16: Antsirabe I | C16: VAKINAKARATRA | D16: Antsirabe II | E16: =IF(D16="","",IF(UPPER(D16)=UPPER(B16),"OUI","NON")) -> NON | F16: 170 | G16: =+$F$2*2 -> 20 | H16: 1 | I16: 1 | J16: =+H16+I16 -> 2
A17: 14 | B17: Antsirabe I | C17: VAKINAKARATRA | D17: Ambatolampy | E17: =IF(D17="","",IF(UPPER(D17)=UPPER(B17),"OUI","NON")) -> NON | F17: =47+23 -> 70 | G17: =+$F$2*2 -> 20 | H17: 1 | I17: 0 | J17: =+H17+I17 -> 1
A18: 15 | B18: Antsirabe I | C18: VAKINAKARATRA | D18: Antanifotsy | E18: =IF(D18="","",IF(UPPER(D18)=UPPER(B18),"OUI","NON")) -> NON | F18: 113 | G18: =+$F$2*2 -> 20 | H18: 1 | I18: 0 | J18: =+H18+I18 -> 1
A19: 18 | B19: Antsirabe I | C19: VAKINAKARATRA | D19: Betafo | E19: =IF(D19="","",IF(UPPER(D19)=UPPER(B19),"OUI","NON")) -> NON | F19: 195 | G19: =+$F$2*2 -> 20 | H19: 1 | I19: 1 | J19: =+H19+I19 -> 2
A20: 19 | B20: Antsirabe I | C20: VAKINAKARATRA | D20: Faratsiho | E20: =IF(D20="","",IF(UPPER(D20)=UPPER(B20),"OUI","NON")) -> NON | F20: 185 | G20: =+$F$2*2 -> 20 | H20: 1 | I20: 1 | J20: =+H20+I20 -> 2
A21: 20 | B21: Antsirabe I | C21: VAKINAKARATRA | D21: Mandoto | E21: =IF(D21="","",IF(UPPER(D21)=UPPER(B21),"OUI","NON")) -> NON | F21: 125 | G21: =+$F$2*2 -> 20 | H21: 1 | I21: 1 | J21: =+H21+I21 -> 2
A22: 23 | B22: Antsiranana I | C22: DIANA | D22: Antsiranana I | E22: =IF(D22="","",IF(UPPER(D22)=UPPER(B22),"OUI","NON")) -> OUI | F22: 1195 | G22: =+$F$2*2 -> 20 | H22: 3 | I22: 2 | J22: =+H22+I22 -> 5
A23: 24 | B23: Antsiranana I | C23: DIANA | D23: Antsiranana II | E23: =IF(D23="","",IF(UPPER(D23)=UPPER(B23),"OUI","NON")) -> NON | F23: 1195 | G23: =+$F$2*2 -> 20 | H23: 3 | I23: 2 | J23: =+H23+I23 -> 5
A24: 21 | B24: Antsiranana I | C24: DIANA | D24: Ambanja | E24: =IF(D24="","",IF(UPPER(D24)=UPPER(B24),"OUI","NON")) -> NON | F24: 956 | G24: =+$F$2*2 -> 20 | H24: 2 | I24: 1 | J24: =+H24+I24 -> 3
A25: 22 | B25: Antsiranana I | C25: DIANA | D25: Ambilobe | E25: =IF(D25="","",IF(UPPER(D25)=UPPER(B25),"OUI","NON")) -> NON | F25: 1060 | G25: =+$F$2*2 -> 20 | H25: 2 | I25: 2 | J25: =+H25+I25 -> 4
A26: 25 | B26: Antsiranana I | C26: DIANA | D26: Nosy Be | E26: =IF(D26="","",IF(UPPER(D26)=UPPER(B26),"OUI","NON")) -> NON | F26: 1016 | G26: =+$F$2*2 -> 20 | H26: 3 | I26: 2 | J26: =+H26+I26 -> 5
A27: 28 | B27: Sambava | C27: SAVA | D27: Sambava | E27: =IF(D27="","",IF(UPPER(D27)=UPPER(B27),"OUI","NON")) -> OUI | F27: 1400 | G27: =+$F$2*2 -> 20 | H27: 2 | I27: 2 | J27: =+H27+I27 -> 4
A28: 26 | B28: Sambava | C28: SAVA | D28: Andapa | E28: =IF(D28="","",IF(UPPER(D28)=UPPER(B28),"OUI","NON")) -> NON | F28: 1520 | G28: =+$F$2*2 -> 20 | H28: 2 | I28: 2 | J28: =+H28+I28 -> 4
A29: 27 | B29: Sambava | C29: SAVA | D29: Antalaha | E29: =IF(D29="","",IF(UPPER(D29)=UPPER(B29),"OUI","NON")) -> NON | F29: 1490 | G29: =+$F$2*2 -> 20 | H29: 2 | I29: 2 | J29: =+H29+I29 -> 4
... A98: 97 | B98: Ambovombe | C98: ANDROY | D98: Tsihombe | E98: =IF(D98="","",IF(UPPER(D98)=UPPER(B98),"OUI","NON")) -> NON | F98: 1315 | G98: =+$F$2*2 -> 20 | H98: 3 | I98: 2 | J98: =+H98+I98 -> 5
B99: Ambovombe | C99: ANDROY | D99: Antanimora | E99: =IF(D99="","",IF(UPPER(D99)=UPPER(B99),"OUI","NON")) -> NON | F99: 945 | G99: =+$F$2*2 -> 20 | H99: 3 | I99: 2 | J99: =+H99+I99 -> 5
A100: 100 | B100: Taolagnaro | C100: ANOSY | D100: Taolagnaro | E100: =IF(D100="","",IF(UPPER(D100)=UPPER(B100),"OUI","NON")) -> OUI | F100: 1140 | G100: =+$F$2*2 -> 20 | H100: 3 | I100: 2 | J100: =+H100+I100 -> 5
A101: 98 | B101: Taolagnaro | C101: ANOSY | D101: Amboasary-Atsimo | E101: =IF(D101="","",IF(UPPER(D101)=UPPER(B101),"OUI","NON")) -> NON | F101: 955 | G101: =+$F$2*2 -> 20 | H101: 3 | I101: 2 | J101: =+H101+I101 -> 5
A102: 99 | B102: Taolagnaro | C102: ANOSY | D102: Betroka | E102: =IF(D102="","",IF(UPPER(D102)=UPPER(B102),"OUI","NON")) -> NON | F102: 760 | G102: =+$F$2*2 -> 20 | H102: 2 | I102: 1 | J102: =+H102+I102 -> 3
A103: 108 | B103: Toliara I | C103: ATSIMO ANDREFANA | D103: Toliara I | E103: =IF(D103="","",IF(UPPER(D103)=UPPER(B103),"OUI","NON")) -> OUI | F103: 975 | G103: =+$F$2*2 -> 20 | H103: 2 | I103: 1 | J103: =+H103+I103 -> 3
A104: 109 | B104: Toliara I | C104: ATSIMO ANDREFANA | D104: Toliara II | E104: =IF(D104="","",IF(UPPER(D104)=UPPER(B104),"OUI","NON")) -> NON | F104: 975 | G104: =+$F$2*2 -> 20 | H104: 2 | I104: 1 | J104: =+H104+I104 -> 3
A105: 101 | B105: Toliara I | C105: ATSIMO ANDREFANA | D105: Ampanihy | E105: =IF(D105="","",IF(UPPER(D105)=UPPER(B105),"OUI","NON")) -> NON | F105: 1135 | G105: =+$F$2*2 -> 20 | H105: 2 | I105: 2 | J105: =+H105+I105 -> 4
A106: 102 | B106: Toliara I | C106: ATSIMO ANDREFANA | D106: Ankazoabo-Atsimo | E106: =IF(D106="","",IF(UPPER(D106)=UPPER(B106),"OUI","NON")) -> NON | F106: 965 | G106: =+$F$2*2 -> 20 | H106: 2 | I106: 2 | J106: =+H106+I106 -> 4
A107: 103 | B107: Toliara I | C107: ATSIMO ANDREFANA | D107: Benenitra | E107: =IF(D107="","",IF(UPPER(D107)=UPPER(B107),"OUI","NON")) -> NON | F107: 1065 | G107: =+$F$2*2 -> 20 | H107: 2 | I107: 2 | J107: =+H107+I107 -> 4
A108: 104 | B108: Toliara I | C108: ATSIMO ANDREFANA | D108: Beroroha | E108: =IF(D108="","",IF(UPPER(D108)=UPPER(B108),"OUI","NON")) -> NON | F108: 1060 | G108: =+$F$2*2 -> 20 | H108: 2 | I108: 2 | J108: =+H108+I108 -> 4
A109: 105 | B109: Toliara I | C109: ATSIMO ANDREFANA | D109: Betioky-Atsimo | E109: =IF(D109="","",IF(UPPER(D109)=UPPER(B109),"OUI","NON")) -> NON | F109: 1000 | G109: =+$F$2*2 -> 20 | H109: 2 | I109: 2 | J109: =+H109+I109 -> 4
...

Sheet LISTES
A1: Type de saisie | B1: FINANCEMENT | C1: RUBRIQUE | D1: LIGNE BUDGETAIRE | E1: INDEMNITES | F1: Avec Déjeuner ou sans Déjeuner | G1: PJ reçue | H1: PJ conforme | I1: Type de PJ | J1: Statut présence
A2: Atelier/Réunion | B2: UNICEF | C2: INDEMNITÉS DES MISSIONNAIRES | D2: Indeminté des équipes centraux | E2: Delai de route | F2: Oui | G2: Oui | H2: Oui | I2: Facture/Bon de livraison | J2: Présent
A3: Supervision | B3: UNFPA | C3: INDEMNITÉS DES MISSIONNAIRES | D3: Indemnité equipes régionaux | E3: Pendant activité | F3: Non | G3: Non | H3: Non | I3: Reçu de paiement | J3: Absent
A4: Formation | B4: UPNNC | C4: INDEMNITÉS DES MISSIONNAIRES | D4: Indemnité Chauffeur | G4: À compléter | H4: À compléter | I4: État de paiement
A5: Acquisition | B5: WISH2 | C5: INDEMNITÉS DES MISSIONNAIRES | D5: Indemnité des AC | I5: Fiche de présence
A6: Mission extérieur | B6: IPAS | C6: DÉPLACEMENTS DES MISSIONNAIRES | D6: Déplacement forfaitaire Equipes centraux | I6: TDR
B7: AUTRES | C7: DÉPLACEMENTS DES MISSIONNAIRES | D7: Déplacement forfaitaire Equipes régionaux | I7: Rapport technique
C8: DÉPLACEMENTS DES MISSIONNAIRES | D8: Déplacement par avion | I8: Ordre de mission
C9: DÉPLACEMENTS DES MISSIONNAIRES | D9: Carburant | I9: Demande de cotation
C10: DÉPLACEMENTS DES MISSIONNAIRES | D10: Location de voiture | I10: PV de selection
C11: DÉPLACEMENTS DES MISSIONNAIRES | D11: Frais de transfert aéroport Interieur/Exterieur | I11: Facture Proforma
C12: DÉPLACEMENTS DES MISSIONNAIRES | D12: Frais Taxi-brousse | I12: Bon de commande
C13: DÉPLACEMENTS DES MISSIONNAIRES | D13: Autre Frais(Assurance,…) | I13: Contrat
C14: RESTAURATION / FRAIS D'ORGANISATION | D14: Eau minérale GM | I14: Autre
C15: RESTAURATION / FRAIS D'ORGANISATION | D15: Eau minérale PM
C16: RESTAURATION / FRAIS D'ORGANISATION | D16: Fontaine d'eau minérale
C17: RESTAURATION / FRAIS D'ORGANISATION | D17: Pause café
C18: RESTAURATION / FRAIS D'ORGANISATION | D18: Déjeuner
C19: RESTAURATION / FRAIS D'ORGANISATION | D19: Location de salle équipée
C20: FOURNITURES | D20: Rame Papier A4
C21: FOURNITURES | D21: Stylo bleu
C22: FOURNITURES | D22: Flip chart
C23: FOURNITURES | D23: Bloc note
C24: FOURNITURES | D24: Chemise cartonnée
C25: FOURNITURES | D25: Masking tape
C26: FOURNITURES | D26: Post it
... C34: ACHAT | D34: Achat de matériels informatiques
C35: AUTRES

Sheet REFERENTIEL_TARIFS
A1: RUBRIQUE | B1: Ligne budgétaire | C1: Type activité | D1: Unité | E1: Zone | F1: Tarif (Ar) | G1: Actif | H1: Observation
A2: INDEMNITÉS DES MISSIONNAIRES | B2: Indeminté | C2: Tous | D2: personne/jour | E2: Région | F2: 200000 | G2: Oui | H2: À confirmer/adapter selon référentiel DSFa
A3: INDEMNITÉS DES MISSIONNAIRES | B3: Indemnité | C3: Tous | D3: personne/jour | E3: District | F3: 150000 | G3: Oui | H3: À confirmer/adapter selon référentiel DSFa
A4: INDEMNITÉS DES MISSIONNAIRES | B4: Indemnité Chauffeur | C4: Tous | D4: personne/jour | E4: Tous | F4: 200000 | G4: Oui | H4: Base reprise du fichier actuel
A5: INDEMNITÉS DES MISSIONNAIRES | B5: Indemnité des AC | C5: FORMATION | D5: personne/jour | E5: District | F5: 60000 | G5: Oui | H5: Base reprise du fichier actuel
A6: DÉPLACEMENTS DES MISSIONNAIRES | B6: Déplacement forfaitaire Equipes centraux | C6: Tous | D6: personne/jour | E6: Antananarivo | F6: 50000 | G6: Oui | H6: Base reprise du fichier actuel
A7: DÉPLACEMENTS DES MISSIONNAIRES | B7: Déplacement forfaitaire Equipes régionaux | C7: Tous | D7: personne/jour | E7: Région | F7: 30000 | G7: Oui | H7: Base reprise du fichier actuel
A8: DÉPLACEMENTS DES MISSIONNAIRES | B8: Déplacement forfaitaire Equipes régionaux | C8: Tous | D8: personne/jour | E8: District | F8: 20000 | G8: Oui | H8: Base reprise du fichier actuel
A9: DÉPLACEMENTS DES MISSIONNAIRES | B9: Déplacement par avion | C9: Tous | D9: personne/jour | E9: Tous | F9: 25000 | G9: Oui | H9: Base reprise du fichier actuel
A10: DÉPLACEMENTS DES MISSIONNAIRES | B10: Carburant | C10: Tous | D10: personne/jour | E10: Tous | F10: 0 | G10: Oui | H10: À confirmer
A11: DÉPLACEMENTS DES MISSIONNAIRES | B11: Location de voiture | C11: Tous | D11: Nombre | E11: Tous | F11: 0 | G11: Oui | H11: À confirmer
A12: DÉPLACEMENTS DES MISSIONNAIRES | B12: Frais de transfert aéroport Exterieur | C12: Tous | D12: personne/nuit | E12: Tous | F12: 500000 | G12: Oui | H12: À renseigner
A13: DÉPLACEMENTS DES MISSIONNAIRES | B13: Frais de transfert aéroport Interieur | C13: Tous | D13: personne/nuit | E13: Antananarivo | F13: 150000 | G13: Oui | H13: À renseigner
... A35: COUVERTURE MÉDIATIQUE | B35: Diffusion de spot TV | C35: ATELIER/FORMATION | D35: Nombre | E35: Tous | F35: 15 | G35: Oui | H35: À renseigner
A36: ACHAT | B36: Achat de crédit de communication | D36: Nombre | E36: Tous | F36: 16 | G36: Oui | H36: À renseigner
A37: ACHAT | B37: Achat de matériels informatiques | D37: Nombre | E37: Tous | F37: 17 | G37: Oui | H37: À renseigner

Sheet LISTES ACTIVITES
A1: Référence activité | B1: Description | C1: Code budget | D1: Année | E1: Période
A2: VALID_PSN_25 | B2: Atelier de validation PSN Activités T4/2025 | D2: 2026
A3: MATINFO_SSEAJ_25 | B3: Achat matériels informatiques _SSEAJ Activités T4/2025
A4: MATINFO_CHEF_25 | B4: Achat matériels informatiques_Chefferie Activités T4/2025
A5: ACHAT_ORD_26 | B5: Achat ordinateurs – Chefferie Activités T2/2026
A6: ACHAT_CRD_26 | B6: Achat crédits téléphoniques Activités T2/2026
A7: BACHE_GGTA_I | B7: Multiplication Bâche GGTA Activités T2/2026
A8: PSN N°1 | B8: Atelier PSN N°01
A9: PLANIF_SE_26 | B9: Atelier de planification / quantification SSEAJ
A10: NORMES_PROCD_26 | B10: Multiplication document Normes et procédures en SR
A11: QUANT_SE_26 | B11: Atelier de quantification SSEAJ
A12: PSN N°2 | B12: Atelier PSN N°02
A13: MENTO_SPF_26 | B13: Atelier d’élaboration du guide d’approche et d’accompagnement – supervision formative, coaching et mentorat
A14: CURRI_SMN_26 | B14: Atelier de finalisation CURRI SMN

Sheet J.Banque
A1: BANQUE: | B1: BNI
A2: COMPTE N. | B2: 26666070102 72
A3: DEVISE
A5: Date | B5: Ref Pieces Jrnl | C5: Type | D5: Ref chq/OV/… | E5: Description | F5: Recettes | G5: Depenses | H5: Solde progressif | I5: BAILLEURS | J5: BENEFICIAIRES
A6: 46023 | B6: BNI.001 | C6: SOLDE | D6: SOLDE | E6: Report de solde | F6: 120388959 | H6: =F6 -> 120388959 | I6: UNICEF
F93: =SUM(F6:F92) -> 120388959 | G93: =SUM(G6:G92) -> 0 | H93: =F93-G93 -> 120388959
B95: Prepare par : | H95: Valide par :

Sheet J.Depenses
A1: JOURNAL DE DEPENSES 2026
I2: 1 | J2: 2 | K2: 3 | L2: 4 | M2: 5 | N2: 6 | O2: 7 | P2: 8
A3: Date d'enregistrement | B3: Date Pieces comptables | C3: Periode autorisee | D3: Fonds: caisse ou banque | E3: REF Decaismnt | F3: Ref pieces de depense | G3: DCT N° | H3: Code Activite | I3: Code Budget | J3: Désignation | K3: Unite | L3: Nbr Jr/Mois | M3: Quantité | N3: Fréquence | O3: P.U. | P3: Montant
P4: =+SUM(P5:P6) -> 0
P5: =+L5*M5*N5*O5 -> 0
P6: =+L6*M6*N6*O6 -> 0
P7: =+L7*M7*N7*O7 -> 0
P9: =+L9*M9*N9*O9 -> 0
P10: =+L10*M10*N10*O10 -> 0
P12: =+L12*M12*N12*O12 -> 0
P14: =+L14*M14*N14*O14 -> 0
P16: =+L16*M16*N16*O16 -> 0
P17: =+L17*M17*N17*O17 -> 0
P18: =+L18*M18*N18*O18 -> 0
P20: =+L20*M20*N20*O20 -> 0
P21: =+L21*M21*N21*O21 -> 0
J23: TOTAL | O23: TOTAL | P23: =SUM(P5:P22) -> 0

Sheet Rappr Banc 
B1: Nom de l'Entite : DIRECTION DE LA SANTE FAMILIALE
B2: Nom de la Banque : BNI ANKORONDRANO
B3: Compte bancaire n° 00005 00007 26666070102 72
B4: Periode :
A6: ETAT DE RAPPROCHEMENT BANCAIRE
A8: JOURNAL DE BANQUE | G8: RELEVE BANCAIRE
A10: SOLDE AVANT RAPPROCHEMENT | G10: SOLDE AVANT RAPPROCHEMENT | K10: =+D10 -> 0
A12: DATE | B12: REF | C12: LIBELLE | D12: DEBIT | E12: CREDIT | G12: DATE | H12: REF | I12: LIBELLE | J12: DEBIT | K12: CREDIT | L12: SOLDE
C31: TOTAL EN CIRCULATION | D31: =SUM(D13:D29) -> 0 | E31: =SUM(E13:E29) -> 0 | I31: TOTAL EN CIRCULATION | J31: =+SUM(J13:J29) -> 0 | K31: =SUM(K13:K29) -> 0 | L31: =+K31-J31 -> 0
C33: SOLDE RAPPROCHE | D33: =D10-E10+D31-E31 -> 0 | I33: SOLDE RAPPROCHE | J33: =K10-J10+K31-J31 -> 0 | L33: =+L14+K31-J31 -> 0
C35: ECART | D35: =D33-J33 -> 0
C37: Prepare par : | I37: Valide par :

Sheet REFERENTIEL_BUDGET
A1: Code activité | B1: Activité | C1: Date début prévue | D1: Date fin prévue | E1: Ligne budgétaire | F1: Unité | G1: Quantité prévue | H1: Nombre de jour | I1: Taux / Montant unitaire (Ar) | J1: Montant alloué (Ar) | K1: Observations
A2: PSN N°1 | B2: =+IFERROR(VLOOKUP(A2,'LISTES ACTIVITES'!$A$2:$B$14,2,FALSE()),"") -> Atelier PSN N°01 | C2: 46153 | D2: 46157 | E2: INDEMNITÉS DES MISSIONNAIRES | F2: jour-personne | G2: 30 | H2: 5 | I2: 150000 | J2: =IF(OR(G2="",I2="",BudgetTable[[#This Row],[Nombre de jour]]=""),"",G2*I2*BudgetTable[[#This Row],[Nombre de jour]]) -> 22500000
A3: PSN N°1 | B3: =+IFERROR(VLOOKUP(A3,'LISTES ACTIVITES'!$A$2:$B$14,2,FALSE()),"") -> Atelier PSN N°01 | C3: 46280 | D3: 46282 | E3: DÉPLACEMENTS DES MISSIONNAIRES | F3: personne | G3: 10 | H3: 1 | I3: 30000 | J3: =IF(OR(G3="",I3="",BudgetTable[[#This Row],[Nombre de jour]]=""),"",G3*I3*BudgetTable[[#This Row],[Nombre de jour]]) -> 300000
A4: PSN N°1 | B4: =+IFERROR(VLOOKUP(A4,'LISTES ACTIVITES'!$A$2:$B$14,2,FALSE()),"") -> Atelier PSN N°01 | C4: 46280 | D4: 46282 | E4: RESTAURATION / ORGANISATION | F4: jour-personne | G4: 30 | H4: 5 | I4: 25000 | J4: =IF(OR(G4="",I4="",BudgetTable[[#This Row],[Nombre de jour]]=""),"",G4*I4*BudgetTable[[#This Row],[Nombre de jour]]) -> 3750000
B5: =+IFERROR(VLOOKUP(A5,'LISTES ACTIVITES'!$A$2:$B$14,2,FALSE()),"") | J5: =IF(OR(G5="",I5=""),"",G5*I5)
B6: =+IFERROR(VLOOKUP(A6,'LISTES ACTIVITES'!$A$2:$B$14,2,FALSE()),"") | J6: =IF(OR(G6="",I6=""),"",G6*I6)
B7: =+IFERROR(VLOOKUP(A7,'LISTES ACTIVITES'!$A$2:$B$14,2,FALSE()),"") | J7: =IF(OR(G7="",I7=""),"",G7*I7)
B8: =+IFERROR(VLOOKUP(A8,'LISTES ACTIVITES'!$A$2:$B$14,2,FALSE()),"") | J8: =IF(OR(G8="",I8=""),"",G8*I8)
B9: =+IFERROR(VLOOKUP(A9,'LISTES ACTIVITES'!$A$2:$B$14,2,FALSE()),"") | J9: =IF(OR(G9="",I9=""),"",G9*I9)
B10: =+IFERROR(VLOOKUP(A10,'LISTES ACTIVITES'!$A$2:$B$14,2,FALSE()),"") | J10: =IF(OR(G10="",I10=""),"",G10*I10)
B11: =+IFERROR(VLOOKUP(A11,'LISTES ACTIVITES'!$A$2:$B$14,2,FALSE()),"") | J11: =IF(OR(G11="",I11=""),"",G11*I11)
B12: =+IFERROR(VLOOKUP(A12,'LISTES ACTIVITES'!$A$2:$B$14,2,FALSE()),"") | J12: =IF(OR(G12="",I12=""),"",G12*I12)
B13: =+IFERROR(VLOOKUP(A13,'LISTES ACTIVITES'!$A$2:$B$14,2,FALSE()),"") | J13: =IF(OR(G13="",I13=""),"",G13*I13)
B14: =+IFERROR(VLOOKUP(A14,'LISTES ACTIVITES'!$A$2:$B$14,2,FALSE()),"") | J14: =IF(OR(G14="",I14=""),"",G14*I14)
B15: =+IFERROR(VLOOKUP(A15,'LISTES ACTIVITES'!$A$2:$B$14,2,FALSE()),"") | J15: =IF(OR(G15="",I15=""),"",G15*I15)
B16: =+IFERROR(VLOOKUP(A16,'LISTES ACTIVITES'!$A$2:$B$14,2,FALSE()),"") | J16: =IF(OR(G16="",I16=""),"",G16*I16)
... B101: =+IFERROR(VLOOKUP(A101,'LISTES ACTIVITES'!$A$2:$B$14,2,FALSE()),"") | J101: =IF(OR(G101="",I101=""),"",G101*I101)

Sheet CONTROLE_PJ
A1: N° | B1: Code activité | C1: Activité | D1: Date début activité | E1: Date fin activité | F1: Date PJ | G1: Ligne budgétaire | H1: Bénéficiaire / Fournisseur | I1: Type de PJ | J1: Montant alloué (Ar) | K1: Montant payé (Ar) | L1: Montant PJ (Ar) | M1: Écart Budget (Ar) | N1: Écart PJ (Ar) | O1: PJ reçue | P1: PJ conforme | Q1: Date PJ cohérente ? | R1: Montant contrôlées (Ar) | S1: Budget indemnités disponible (Ar) | T1: Contrôle présence/indemnité | U1: Observation | V1: Statut final
A2: =ROW()-1 -> 1 | B2: PSN N°1 | C2: =+IFERROR(VLOOKUP(ControlePJTable[[#This Row],[Code activité]],'LISTES ACTIVITES'!$A$1:$B$38,2,FALSE()),"") -> Atelier PSN N°01 | D2: 46153 | E2: 46157 | F2: 46223 | G2: RESTAURATION / ORGANISATION | H2: camillo traiteur | I2: Facture | J2: 3750000 | K2: 3750000 | L2: 3750000 | M2: =IF(OR(J2="",K2=""),"",K2-J2) -> 0 | N2: =IF(OR(K2="",L2=""),"",L2-K2) -> 0 | O2: Oui | P2: Oui | Q2: =IF(OR(D2="",E2="",F2=""),"",IF(AND(F2>=D2,E2<=F2),"Oui","Non")) -> Oui | R2: 3750000 | S2: =IF(B2="","",SUMIFS(REFERENTIEL_BUDGET!$J$2:$J$101,REFERENTIEL_BUDGET!$A$2:$A$101,B2,REFERENTIEL_BUDGET!$E$2:$E$101,G2)) -> 3750000 | T2: =IF(B2="","",IF(COUNTIFS(PRESENCES_INDEMNITES!$B$2:$B$501,B2,PRESENCES_INDEMNITES!$S$2:$S$501,"<>CONFORME",PRESENCES_INDEMNITES!$S$2:$S$501,"<>")>0,"Anomalie détectée",IF(R2>S2,"Dépassement budget indemnités","Conforme"))) -> Conforme | V2: =IF(O2="Non","PJ non reçue",IF(O2="","",IF(Q2="Non","Date PJ non conforme",IF(OR(M2>0,N2<>0,P2="Non",T2="Anomalie détectée",T2="Dépassement budget indemnités"),"Non conforme",IF(P2="À vérifier","À vérifier","Conforme"))))) -> Conforme
A3: =ROW()-1 -> 2 | B3: PSN N°1 | C3: =+IFERROR(VLOOKUP(ControlePJTable[[#This Row],[Code activité]],'LISTES ACTIVITES'!$A$1:$B$38,2,FALSE()),"") -> Atelier PSN N°01 | D3: 46153 | E3: 46157 | F3: 46159 | G3: INDEMNITÉS DES MISSIONNAIRES | H3: Missionnaires | I3: État de paiement | J3: 22500000 | K3: 10800000 | L3: 10800000 | M3: =IF(OR(J3="",K3=""),"",K3-J3) -> -11700000 | N3: =IF(OR(K3="",L3=""),"",L3-K3) -> 0 | O3: Oui | P3: Oui | Q3: =IF(OR(D3="",E3="",F3=""),"",IF(AND(F3>=D3,E3<=F3),"Oui","Non")) -> Oui | R3: =IF(B3="","",SUMIFS(PRESENCES_INDEMNITES!$N$2:$N$501,PRESENCES_INDEMNITES!$B$2:$B$501,B3,PRESENCES_INDEMNITES!$S$2:$S$501,"CONFORME")) -> 10800000 | S3: =IF(B3="","",SUMIFS(REFERENTIEL_BUDGET!$J$2:$J$101,REFERENTIEL_BUDGET!$A$2:$A$101,B3,REFERENTIEL_BUDGET!$E$2:$E$101,G3)) -> 22500000 | T3: =IF(B3="","",IF(COUNTIFS(PRESENCES_INDEMNITES!$B$2:$B$501,B3,PRESENCES_INDEMNITES!$S$2:$S$501,"<>CONFORME",PRESENCES_INDEMNITES!$S$2:$S$501,"<>")>0,"Anomalie détectée",IF(R3>S3,"Dépassement budget indemnités","Conforme"))) -> Conforme | V3: =IF(O3="Non","PJ non reçue",IF(O3="","",IF(Q3="Non","Date PJ non conforme",IF(OR(M3>0,N3<>0,P3="Non",T3="Anomalie détectée",T3="Dépassement budget indemnités"),"Non conforme",IF(P3="À vérifier","À vérifier","Conforme"))))) -> Conforme
A4: =ROW()-1 -> 3 | C4: =+IFERROR(VLOOKUP(ControlePJTable[[#This Row],[Code activité]],'LISTES ACTIVITES'!$A$1:$B$38,2,FALSE()),"") | G4: DÉPLACEMENTS DES MISSIONNAIRES | M4: =IF(OR(J4="",K4=""),"",K4-J4) | N4: =IF(OR(K4="",L4=""),"",L4-K4) | Q4: =IF(OR(D4="",E4="",F4=""),"",IF(AND(F4>=D4,E4<=F4),"Oui","Non")) | R4: =IF(B4="","",SUMIFS(PRESENCES_INDEMNITES!$N$2:$N$501,PRESENCES_INDEMNITES!$B$2:$B$501,B4,PRESENCES_INDEMNITES!$S$2:$S$501,"CONFORME")) | S4: =IF(B4="","",SUMIFS(REFERENTIEL_BUDGET!$J$2:$J$101,REFERENTIEL_BUDGET!$A$2:$A$101,B4,REFERENTIEL_BUDGET!$E$2:$E$101,G4)) | T4: =IF(B4="","",IF(COUNTIFS(PRESENCES_INDEMNITES!$B$2:$B$501,B4,PRESENCES_INDEMNITES!$S$2:$S$501,"<>CONFORME",PRESENCES_INDEMNITES!$S$2:$S$501,"<>")>0,"Anomalie détectée",IF(R4>S4,"Dépassement budget indemnités","Conforme"))) | V4: =IF(O4="Non","PJ non reçue",IF(O4="","",IF(Q4="Non","Date PJ non conforme",IF(OR(M4>0,N4<>0,P4="Non",T4="Anomalie détectée",T4="Dépassement budget indemnités"),"Non conforme",IF(P4="À vérifier","À vérifier","Conforme")))))
A5: =ROW()-1 -> 4 | C5: =+IFERROR(VLOOKUP(ControlePJTable[[#This Row],[Code activité]],'LISTES ACTIVITES'!$A$1:$B$38,2,FALSE()),"") | M5: =IF(OR(J5="",K5=""),"",K5-J5) | N5: =IF(OR(K5="",L5=""),"",L5-K5) | Q5: =IF(OR(D5="",E5="",F5=""),"",IF(AND(F5>=D5,E5<=F5),"Oui","Non")) | R5: =IF(B5="","",SUMIFS(PRESENCES_INDEMNITES!$N$2:$N$501,PRESENCES_INDEMNITES!$B$2:$B$501,B5,PRESENCES_INDEMNITES!$S$2:$S$501,"CONFORME")) | S5: =IF(B5="","",SUMIFS(REFERENTIEL_BUDGET!$J$2:$J$101,REFERENTIEL_BUDGET!$A$2:$A$101,B5,REFERENTIEL_BUDGET!$E$2:$E$101,G5)) | T5: =IF(B5="","",IF(COUNTIFS(PRESENCES_INDEMNITES!$B$2:$B$501,B5,PRESENCES_INDEMNITES!$S$2:$S$501,"<>CONFORME",PRESENCES_INDEMNITES!$S$2:$S$501,"<>")>0,"Anomalie détectée",IF(R5>S5,"Dépassement budget indemnités","Conforme"))) | V5: =IF(O5="Non","PJ non reçue",IF(O5="","",IF(Q5="Non","Date PJ non conforme",IF(OR(M5>0,N5<>0,P5="Non",T5="Anomalie détectée",T5="Dépassement budget indemnités"),"Non conforme",IF(P5="À vérifier","À vérifier","Conforme")))))
A6: =ROW()-1 -> 5 | C6: =+IFERROR(VLOOKUP(ControlePJTable[[#This Row],[Code activité]],'LISTES ACTIVITES'!$A$1:$B$38,2,FALSE()),"") | M6: =IF(OR(J6="",K6=""),"",K6-J6) | N6: =IF(OR(K6="",L6=""),"",L6-K6) | Q6: =IF(OR(D6="",E6="",F6=""),"",IF(AND(F6>=D6,E6<=F6),"Oui","Non")) | R6: =IF(B6="","",SUMIFS(PRESENCES_INDEMNITES!$N$2:$N$501,PRESENCES_INDEMNITES!$B$2:$B$501,B6,PRESENCES_INDEMNITES!$S$2:$S$501,"CONFORME")) | S6: =IF(B6="","",SUMIFS(REFERENTIEL_BUDGET!$J$2:$J$101,REFERENTIEL_BUDGET!$A$2:$A$101,B6,REFERENTIEL_BUDGET!$E$2:$E$101,G6)) | T6: =IF(B6="","",IF(COUNTIFS(PRESENCES_INDEMNITES!$B$2:$B$501,B6,PRESENCES_INDEMNITES!$S$2:$S$501,"<>CONFORME",PRESENCES_INDEMNITES!$S$2:$S$501,"<>")>0,"Anomalie détectée",IF(R6>S6,"Dépassement budget indemnités","Conforme"))) | V6: =IF(O6="Non","PJ non reçue",IF(O6="","",IF(Q6="Non","Date PJ non conforme",IF(OR(M6>0,N6<>0,P6="Non",T6="Anomalie détectée",T6="Dépassement budget indemnités"),"Non conforme",IF(P6="À vérifier","À vérifier","Conforme")))))
A7: =ROW()-1 -> 6 | C7: =+IFERROR(VLOOKUP(ControlePJTable[[#This Row],[Code activité]],'LISTES ACTIVITES'!$A$1:$B$38,2,FALSE()),"") | M7: =IF(OR(J7="",K7=""),"",K7-J7) | N7: =IF(OR(K7="",L7=""),"",L7-K7) | Q7: =IF(OR(D7="",E7="",F7=""),"",IF(AND(F7>=D7,E7<=F7),"Oui","Non")) | R7: =IF(B7="","",SUMIFS(PRESENCES_INDEMNITES!$N$2:$N$501,PRESENCES_INDEMNITES!$B$2:$B$501,B7,PRESENCES_INDEMNITES!$S$2:$S$501,"CONFORME")) | S7: =IF(B7="","",SUMIFS(REFERENTIEL_BUDGET!$J$2:$J$101,REFERENTIEL_BUDGET!$A$2:$A$101,B7,REFERENTIEL_BUDGET!$E$2:$E$101,G7)) | T7: =IF(B7="","",IF(COUNTIFS(PRESENCES_INDEMNITES!$B$2:$B$501,B7,PRESENCES_INDEMNITES!$S$2:$S$501,"<>CONFORME",PRESENCES_INDEMNITES!$S$2:$S$501,"<>")>0,"Anomalie détectée",IF(R7>S7,"Dépassement budget indemnités","Conforme"))) | V7: =IF(O7="Non","PJ non reçue",IF(O7="","",IF(Q7="Non","Date PJ non conforme",IF(OR(M7>0,N7<>0,P7="Non",T7="Anomalie détectée",T7="Dépassement budget indemnités"),"Non conforme",IF(P7="À vérifier","À vérifier","Conforme")))))
A8: =ROW()-1 -> 7 | C8: =+IFERROR(VLOOKUP(ControlePJTable[[#This Row],[Code activité]],'LISTES ACTIVITES'!$A$1:$B$38,2,FALSE()),"") | M8: =IF(OR(J8="",K8=""),"",K8-J8) | N8: =IF(OR(K8="",L8=""),"",L8-K8) | Q8: =IF(OR(D8="",E8="",F8=""),"",IF(AND(F8>=D8,E8<=F8),"Oui","Non")) | R8: =IF(B8="","",SUMIFS(PRESENCES_INDEMNITES!$N$2:$N$501,PRESENCES_INDEMNITES!$B$2:$B$501,B8,PRESENCES_INDEMNITES!$S$2:$S$501,"CONFORME")) | S8: =IF(B8="","",SUMIFS(REFERENTIEL_BUDGET!$J$2:$J$101,REFERENTIEL_BUDGET!$A$2:$A$101,B8,REFERENTIEL_BUDGET!$E$2:$E$101,G8)) | T8: =IF(B8="","",IF(COUNTIFS(PRESENCES_INDEMNITES!$B$2:$B$501,B8,PRESENCES_INDEMNITES!$S$2:$S$501,"<>CONFORME",PRESENCES_INDEMNITES!$S$2:$S$501,"<>")>0,"Anomalie détectée",IF(R8>S8,"Dépassement budget indemnités","Conforme"))) | V8: =IF(O8="Non","PJ non reçue",IF(O8="","",IF(Q8="Non","Date PJ non conforme",IF(OR(M8>0,N8<>0,P8="Non",T8="Anomalie détectée",T8="Dépassement budget indemnités"),"Non conforme",IF(P8="À vérifier","À vérifier","Conforme")))))
A9: =ROW()-1 -> 8 | C9: =+IFERROR(VLOOKUP(ControlePJTable[[#This Row],[Code activité]],'LISTES ACTIVITES'!$A$1:$B$38,2,FALSE()),"") | M9: =IF(OR(J9="",K9=""),"",K9-J9) | N9: =IF(OR(K9="",L9=""),"",L9-K9) | Q9: =IF(OR(D9="",E9="",F9=""),"",IF(AND(F9>=D9,E9<=F9),"Oui","Non")) | R9: =IF(B9="","",SUMIFS(PRESENCES_INDEMNITES!$N$2:$N$501,PRESENCES_INDEMNITES!$B$2:$B$501,B9,PRESENCES_INDEMNITES!$S$2:$S$501,"CONFORME")) | S9: =IF(B9="","",SUMIFS(REFERENTIEL_BUDGET!$J$2:$J$101,REFERENTIEL_BUDGET!$A$2:$A$101,B9,REFERENTIEL_BUDGET!$E$2:$E$101,G9)) | T9: =IF(B9="","",IF(COUNTIFS(PRESENCES_INDEMNITES!$B$2:$B$501,B9,PRESENCES_INDEMNITES!$S$2:$S$501,"<>CONFORME",PRESENCES_INDEMNITES!$S$2:$S$501,"<>")>0,"Anomalie détectée",IF(R9>S9,"Dépassement budget indemnités","Conforme"))) | V9: =IF(O9="Non","PJ non reçue",IF(O9="","",IF(Q9="Non","Date PJ non conforme",IF(OR(M9>0,N9<>0,P9="Non",T9="Anomalie détectée",T9="Dépassement budget indemnités"),"Non conforme",IF(P9="À vérifier","À vérifier","Conforme")))))
A10: =ROW()-1 -> 9 | C10: =+IFERROR(VLOOKUP(ControlePJTable[[#This Row],[Code activité]],'LISTES ACTIVITES'!$A$1:$B$38,2,FALSE()),"") | M10: =IF(OR(J10="",K10=""),"",K10-J10) | N10: =IF(OR(K10="",L10=""),"",L10-K10) | Q10: =IF(OR(D10="",E10="",F10=""),"",IF(AND(F10>=D10,E10<=F10),"Oui","Non")) | R10: =IF(B10="","",SUMIFS(PRESENCES_INDEMNITES!$N$2:$N$501,PRESENCES_INDEMNITES!$B$2:$B$501,B10,PRESENCES_INDEMNITES!$S$2:$S$501,"CONFORME")) | S10: =IF(B10="","",SUMIFS(REFERENTIEL_BUDGET!$J$2:$J$101,REFERENTIEL_BUDGET!$A$2:$A$101,B10,REFERENTIEL_BUDGET!$E$2:$E$101,"Indemnités participants")) | T10: =IF(B10="","",IF(COUNTIFS(PRESENCES_INDEMNITES!$B$2:$B$501,B10,PRESENCES_INDEMNITES!$S$2:$S$501,"<>CONFORME",PRESENCES_INDEMNITES!$S$2:$S$501,"<>")>0,"Anomalie détectée",IF(R10>S10,"Dépassement budget indemnités","Conforme"))) | V10: =IF(O10="Non","PJ non reçue",IF(O10="","",IF(Q10="Non","Date PJ non conforme",IF(OR(M10>0,N10<>0,P10="Non",T10="Anomalie détectée",T10="Dépassement budget indemnités"),"Non conforme",IF(P10="À vérifier","À vérifier","Conforme")))))
A11: =ROW()-1 -> 10 | C11: =+IFERROR(VLOOKUP(ControlePJTable[[#This Row],[Code activité]],'LISTES ACTIVITES'!$A$1:$B$38,2,FALSE()),"") | M11: =IF(OR(J11="",K11=""),"",K11-J11) | N11: =IF(OR(K11="",L11=""),"",L11-K11) | Q11: =IF(OR(D11="",E11="",F11=""),"",IF(AND(F11>=D11,E11<=F11),"Oui","Non")) | R11: =IF(B11="","",SUMIFS(PRESENCES_INDEMNITES!$N$2:$N$501,PRESENCES_INDEMNITES!$B$2:$B$501,B11,PRESENCES_INDEMNITES!$S$2:$S$501,"CONFORME")) | S11: =IF(B11="","",SUMIFS(REFERENTIEL_BUDGET!$J$2:$J$101,REFERENTIEL_BUDGET!$A$2:$A$101,B11,REFERENTIEL_BUDGET!$E$2:$E$101,"Indemnités participants")) | T11: =IF(B11="","",IF(COUNTIFS(PRESENCES_INDEMNITES!$B$2:$B$501,B11,PRESENCES_INDEMNITES!$S$2:$S$501,"<>CONFORME",PRESENCES_INDEMNITES!$S$2:$S$501,"<>")>0,"Anomalie détectée",IF(R11>S11,"Dépassement budget indemnités","Conforme"))) | V11: =IF(O11="Non","PJ non reçue",IF(O11="","",IF(Q11="Non","Date PJ non conforme",IF(OR(M11>0,N11<>0,P11="Non",T11="Anomalie détectée",T11="Dépassement budget indemnités"),"Non conforme",IF(P11="À vérifier","À vérifier","Conforme")))))
A12: =ROW()-1 -> 11 | C12: =+IFERROR(VLOOKUP(ControlePJTable[[#This Row],[Code activité]],'LISTES ACTIVITES'!$A$1:$B$38,2,FALSE()),"") | M12: =IF(OR(J12="",K12=""),"",K12-J12) | N12: =IF(OR(K12="",L12=""),"",L12-K12) | Q12: =IF(OR(D12="",E12="",F12=""),"",IF(AND(F12>=D12,E12<=F12),"Oui","Non")) | R12: =IF(B12="","",SUMIFS(PRESENCES_INDEMNITES!$N$2:$N$501,PRESENCES_INDEMNITES!$B$2:$B$501,B12,PRESENCES_INDEMNITES!$S$2:$S$501,"CONFORME")) | S12: =IF(B12="","",SUMIFS(REFERENTIEL_BUDGET!$J$2:$J$101,REFERENTIEL_BUDGET!$A$2:$A$101,B12,REFERENTIEL_BUDGET!$E$2:$E$101,"Indemnités participants")) | T12: =IF(B12="","",IF(COUNTIFS(PRESENCES_INDEMNITES!$B$2:$B$501,B12,PRESENCES_INDEMNITES!$S$2:$S$501,"<>CONFORME",PRESENCES_INDEMNITES!$S$2:$S$501,"<>")>0,"Anomalie détectée",IF(R12>S12,"Dépassement budget indemnités","Conforme"))) | V12: =IF(O12="Non","PJ non reçue",IF(O12="","",IF(Q12="Non","Date PJ non conforme",IF(OR(M12>0,N12<>0,P12="Non",T12="Anomalie détectée",T12="Dépassement budget indemnités"),"Non conforme",IF(P12="À vérifier","À vérifier","Conforme")))))
A13: =ROW()-1 -> 12 | C13: =+IFERROR(VLOOKUP(ControlePJTable[[#This Row],[Code activité]],'LISTES ACTIVITES'!$A$1:$B$38,2,FALSE()),"") | M13: =IF(OR(J13="",K13=""),"",K13-J13) | N13: =IF(OR(K13="",L13=""),"",L13-K13) | Q13: =IF(OR(D13="",E13="",F13=""),"",IF(AND(F13>=D13,E13<=F13),"Oui","Non")) | R13: =IF(B13="","",SUMIFS(PRESENCES_INDEMNITES!$N$2:$N$501,PRESENCES_INDEMNITES!$B$2:$B$501,B13,PRESENCES_INDEMNITES!$S$2:$S$501,"CONFORME")) | S13: =IF(B13="","",SUMIFS(REFERENTIEL_BUDGET!$J$2:$J$101,REFERENTIEL_BUDGET!$A$2:$A$101,B13,REFERENTIEL_BUDGET!$E$2:$E$101,"Indemnités participants")) | T13: =IF(B13="","",IF(COUNTIFS(PRESENCES_INDEMNITES!$B$2:$B$501,B13,PRESENCES_INDEMNITES!$S$2:$S$501,"<>CONFORME",PRESENCES_INDEMNITES!$S$2:$S$501,"<>")>0,"Anomalie détectée",IF(R13>S13,"Dépassement budget indemnités","Conforme"))) | V13: =IF(O13="Non","PJ non reçue",IF(O13="","",IF(Q13="Non","Date PJ non conforme",IF(OR(M13>0,N13<>0,P13="Non",T13="Anomalie détectée",T13="Dépassement budget indemnités"),"Non conforme",IF(P13="À vérifier","À vérifier","Conforme")))))
A14: =ROW()-1 -> 13 | C14: =+IFERROR(VLOOKUP(ControlePJTable[[#This Row],[Code activité]],'LISTES ACTIVITES'!$A$1:$B$38,2,FALSE()),"") | M14: =IF(OR(J14="",K14=""),"",K14-J14) | N14: =IF(OR(K14="",L14=""),"",L14-K14) | Q14: =IF(OR(D14="",E14="",F14=""),"",IF(AND(F14>=D14,E14<=F14),"Oui","Non")) | R14: =IF(B14="","",SUMIFS(PRESENCES_INDEMNITES!$N$2:$N$501,PRESENCES_INDEMNITES!$B$2:$B$501,B14,PRESENCES_INDEMNITES!$S$2:$S$501,"CONFORME")) | S14: =IF(B14="","",SUMIFS(REFERENTIEL_BUDGET!$J$2:$J$101,REFERENTIEL_BUDGET!$A$2:$A$101,B14,REFERENTIEL_BUDGET!$E$2:$E$101,"Indemnités participants")) | T14: =IF(B14="","",IF(COUNTIFS(PRESENCES_INDEMNITES!$B$2:$B$501,B14,PRESENCES_INDEMNITES!$S$2:$S$501,"<>CONFORME",PRESENCES_INDEMNITES!$S$2:$S$501,"<>")>0,"Anomalie détectée",IF(R14>S14,"Dépassement budget indemnités","Conforme"))) | V14: =IF(O14="Non","PJ non reçue",IF(O14="","",IF(Q14="Non","Date PJ non conforme",IF(OR(M14>0,N14<>0,P14="Non",T14="Anomalie détectée",T14="Dépassement budget indemnités"),"Non conforme",IF(P14="À vérifier","À vérifier","Conforme")))))
A15: =ROW()-1 -> 14 | C15: =+IFERROR(VLOOKUP(ControlePJTable[[#This Row],[Code activité]],'LISTES ACTIVITES'!$A$1:$B$38,2,FALSE()),"") | M15: =IF(OR(J15="",K15=""),"",K15-J15) | N15: =IF(OR(K15="",L15=""),"",L15-K15) | Q15: =IF(OR(D15="",E15="",F15=""),"",IF(AND(F15>=D15,E15<=F15),"Oui","Non")) | R15: =IF(B15="","",SUMIFS(PRESENCES_INDEMNITES!$N$2:$N$501,PRESENCES_INDEMNITES!$B$2:$B$501,B15,PRESENCES_INDEMNITES!$S$2:$S$501,"CONFORME")) | S15: =IF(B15="","",SUMIFS(REFERENTIEL_BUDGET!$J$2:$J$101,REFERENTIEL_BUDGET!$A$2:$A$101,B15,REFERENTIEL_BUDGET!$E$2:$E$101,"Indemnités participants")) | T15: =IF(B15="","",IF(COUNTIFS(PRESENCES_INDEMNITES!$B$2:$B$501,B15,PRESENCES_INDEMNITES!$S$2:$S$501,"<>CONFORME",PRESENCES_INDEMNITES!$S$2:$S$501,"<>")>0,"Anomalie détectée",IF(R15>S15,"Dépassement budget indemnités","Conforme"))) | V15: =IF(O15="Non","PJ non reçue",IF(O15="","",IF(Q15="Non","Date PJ non conforme",IF(OR(M15>0,N15<>0,P15="Non",T15="Anomalie détectée",T15="Dépassement budget indemnités"),"Non conforme",IF(P15="À vérifier","À vérifier","Conforme")))))
A16: =ROW()-1 -> 15 | C16: =+IFERROR(VLOOKUP(ControlePJTable[[#This Row],[Code activité]],'LISTES ACTIVITES'!$A$1:$B$38,2,FALSE()),"") | M16: =IF(OR(J16="",K16=""),"",K16-J16) | N16: =IF(OR(K16="",L16=""),"",L16-K16) | Q16: =IF(OR(D16="",E16="",F16=""),"",IF(AND(F16>=D16,E16<=F16),"Oui","Non")) | R16: =IF(B16="","",SUMIFS(PRESENCES_INDEMNITES!$N$2:$N$501,PRESENCES_INDEMNITES!$B$2:$B$501,B16,PRESENCES_INDEMNITES!$S$2:$S$501,"CONFORME")) | S16: =IF(B16="","",SUMIFS(REFERENTIEL_BUDGET!$J$2:$J$101,REFERENTIEL_BUDGET!$A$2:$A$101,B16,REFERENTIEL_BUDGET!$E$2:$E$101,"Indemnités participants")) | T16: =IF(B16="","",IF(COUNTIFS(PRESENCES_INDEMNITES!$B$2:$B$501,B16,PRESENCES_INDEMNITES!$S$2:$S$501,"<>CONFORME",PRESENCES_INDEMNITES!$S$2:$S$501,"<>")>0,"Anomalie détectée",IF(R16>S16,"Dépassement budget indemnités","Conforme"))) | V16: =IF(O16="Non","PJ non reçue",IF(O16="","",IF(Q16="Non","Date PJ non conforme",IF(OR(M16>0,N16<>0,P16="Non",T16="Anomalie détectée",T16="Dépassement budget indemnités"),"Non conforme",IF(P16="À vérifier","À vérifier","Conforme")))))
A17: =ROW()-1 -> 16 | C17: =+IFERROR(VLOOKUP(ControlePJTable[[#This Row],[Code activité]],'LISTES ACTIVITES'!$A$1:$B$38,2,FALSE()),"") | M17: =IF(OR(J17="",K17=""),"",K17-J17) | N17: =IF(OR(K17="",L17=""),"",L17-K17) | Q17: =IF(OR(D17="",E17="",F17=""),"",IF(AND(F17>=D17,E17<=F17),"Oui","Non")) | R17: =IF(B17="","",SUMIFS(PRESENCES_INDEMNITES!$N$2:$N$501,PRESENCES_INDEMNITES!$B$2:$B$501,B17,PRESENCES_INDEMNITES!$S$2:$S$501,"CONFORME")) | S17: =IF(B17="","",SUMIFS(REFERENTIEL_BUDGET!$J$2:$J$101,REFERENTIEL_BUDGET!$A$2:$A$101,B17,REFERENTIEL_BUDGET!$E$2:$E$101,"Indemnités participants")) | T17: =IF(B17="","",IF(COUNTIFS(PRESENCES_INDEMNITES!$B$2:$B$501,B17,PRESENCES_INDEMNITES!$S$2:$S$501,"<>CONFORME",PRESENCES_INDEMNITES!$S$2:$S$501,"<>")>0,"Anomalie détectée",IF(R17>S17,"Dépassement budget indemnités","Conforme"))) | V17: =IF(O17="Non","PJ non reçue",IF(O17="","",IF(Q17="Non","Date PJ non conforme",IF(OR(M17>0,N17<>0,P17="Non",T17="Anomalie détectée",T17="Dépassement budget indemnités"),"Non conforme",IF(P17="À vérifier","À vérifier","Conforme")))))
A18: =ROW()-1 -> 17 | C18: =+IFERROR(VLOOKUP(ControlePJTable[[#This Row],[Code activité]],'LISTES ACTIVITES'!$A$1:$B$38,2,FALSE()),"") | M18: =IF(OR(J18="",K18=""),"",K18-J18) | N18: =IF(OR(K18="",L18=""),"",L18-K18) | Q18: =IF(OR(D18="",E18="",F18=""),"",IF(AND(F18>=D18,E18<=F18),"Oui","Non")) | R18: =IF(B18="","",SUMIFS(PRESENCES_INDEMNITES!$N$2:$N$501,PRESENCES_INDEMNITES!$B$2:$B$501,B18,PRESENCES_INDEMNITES!$S$2:$S$501,"CONFORME")) | S18: =IF(B18="","",SUMIFS(REFERENTIEL_BUDGET!$J$2:$J$101,REFERENTIEL_BUDGET!$A$2:$A$101,B18,REFERENTIEL_BUDGET!$E$2:$E$101,"Indemnités participants")) | T18: =IF(B18="","",IF(COUNTIFS(PRESENCES_INDEMNITES!$B$2:$B$501,B18,PRESENCES_INDEMNITES!$S$2:$S$501,"<>CONFORME",PRESENCES_INDEMNITES!$S$2:$S$501,"<>")>0,"Anomalie détectée",IF(R18>S18,"Dépassement budget indemnités","Conforme"))) | V18: =IF(O18="Non","PJ non reçue",IF(O18="","",IF(Q18="Non","Date PJ non conforme",IF(OR(M18>0,N18<>0,P18="Non",T18="Anomalie détectée",T18="Dépassement budget indemnités"),"Non conforme",IF(P18="À vérifier","À vérifier","Conforme")))))
A19: =ROW()-1 -> 18 | C19: =+IFERROR(VLOOKUP(ControlePJTable[[#This Row],[Code activité]],'LISTES ACTIVITES'!$A$1:$B$38,2,FALSE()),"") | M19: =IF(OR(J19="",K19=""),"",K19-J19) | N19: =IF(OR(K19="",L19=""),"",L19-K19) | Q19: =IF(OR(D19="",E19="",F19=""),"",IF(AND(F19>=D19,E19<=F19),"Oui","Non")) | R19: =IF(B19="","",SUMIFS(PRESENCES_INDEMNITES!$N$2:$N$501,PRESENCES_INDEMNITES!$B$2:$B$501,B19,PRESENCES_INDEMNITES!$S$2:$S$501,"CONFORME")) | S19: =IF(B19="","",SUMIFS(REFERENTIEL_BUDGET!$J$2:$J$101,REFERENTIEL_BUDGET!$A$2:$A$101,B19,REFERENTIEL_BUDGET!$E$2:$E$101,"Indemnités participants")) | T19: =IF(B19="","",IF(COUNTIFS(PRESENCES_INDEMNITES!$B$2:$B$501,B19,PRESENCES_INDEMNITES!$S$2:$S$501,"<>CONFORME",PRESENCES_INDEMNITES!$S$2:$S$501,"<>")>0,"Anomalie détectée",IF(R19>S19,"Dépassement budget indemnités","Conforme"))) | V19: =IF(O19="Non","PJ non reçue",IF(O19="","",IF(Q19="Non","Date PJ non conforme",IF(OR(M19>0,N19<>0,P19="Non",T19="Anomalie détectée",T19="Dépassement budget indemnités"),"Non conforme",IF(P19="À vérifier","À vérifier","Conforme")))))
A20: =ROW()-1 -> 19 | C20: =+IFERROR(VLOOKUP(ControlePJTable[[#This Row],[Code activité]],'LISTES ACTIVITES'!$A$1:$B$38,2,FALSE()),"") | M20: =IF(OR(J20="",K20=""),"",K20-J20) | N20: =IF(OR(K20="",L20=""),"",L20-K20) | Q20: =IF(OR(D20="",E20="",F20=""),"",IF(AND(F20>=D20,E20<=F20),"Oui","Non")) | R20: =IF(B20="","",SUMIFS(PRESENCES_INDEMNITES!$N$2:$N$501,PRESENCES_INDEMNITES!$B$2:$B$501,B20,PRESENCES_INDEMNITES!$S$2:$S$501,"CONFORME")) | S20: =IF(B20="","",SUMIFS(REFERENTIEL_BUDGET!$J$2:$J$101,REFERENTIEL_BUDGET!$A$2:$A$101,B20,REFERENTIEL_BUDGET!$E$2:$E$101,"Indemnités participants")) | T20: =IF(B20="","",IF(COUNTIFS(PRESENCES_INDEMNITES!$B$2:$B$501,B20,PRESENCES_INDEMNITES!$S$2:$S$501,"<>CONFORME",PRESENCES_INDEMNITES!$S$2:$S$501,"<>")>0,"Anomalie détectée",IF(R20>S20,"Dépassement budget indemnités","Conforme"))) | V20: =IF(O20="Non","PJ non reçue",IF(O20="","",IF(Q20="Non","Date PJ non conforme",IF(OR(M20>0,N20<>0,P20="Non",T20="Anomalie détectée",T20="Dépassement budget indemnités"),"Non conforme",IF(P20="À vérifier","À vérifier","Conforme")))))
A21: =ROW()-1 -> 20 | C21: =+IFERROR(VLOOKUP(ControlePJTable[[#This Row],[Code activité]],'LISTES ACTIVITES'!$A$1:$B$38,2,FALSE()),"") | M21: =IF(OR(J21="",K21=""),"",K21-J21) | N21: =IF(OR(K21="",L21=""),"",L21-K21) | Q21: =IF(OR(D21="",E21="",F21=""),"",IF(AND(F21>=D21,E21<=F21),"Oui","Non")) | R21: =IF(B21="","",SUMIFS(PRESENCES_INDEMNITES!$N$2:$N$501,PRESENCES_INDEMNITES!$B$2:$B$501,B21,PRESENCES_INDEMNITES!$S$2:$S$501,"CONFORME")) | S21: =IF(B21="","",SUMIFS(REFERENTIEL_BUDGET!$J$2:$J$101,REFERENTIEL_BUDGET!$A$2:$A$101,B21,REFERENTIEL_BUDGET!$E$2:$E$101,"Indemnités participants")) | T21: =IF(B21="","",IF(COUNTIFS(PRESENCES_INDEMNITES!$B$2:$B$501,B21,PRESENCES_INDEMNITES!$S$2:$S$501,"<>CONFORME",PRESENCES_INDEMNITES!$S$2:$S$501,"<>")>0,"Anomalie détectée",IF(R21>S21,"Dépassement budget indemnités","Conforme"))) | V21: =IF(O21="Non","PJ non reçue",IF(O21="","",IF(Q21="Non","Date PJ non conforme",IF(OR(M21>0,N21<>0,P21="Non",T21="Anomalie détectée",T21="Dépassement budget indemnités"),"Non conforme",IF(P21="À vérifier","À vérifier","Conforme")))))
... A301: =ROW()-1 -> 300 | C301: =+IFERROR(VLOOKUP(ControlePJTable[[#This Row],[Code activité]],'LISTES ACTIVITES'!$A$1:$B$38,2,FALSE()),"") | M301: =IF(OR(J301="",K301=""),"",K301-J301) | N301: =IF(OR(K301="",L301=""),"",L301-K301) | Q301: =IF(OR(D301="",E301="",F301=""),"",IF(AND(F301>=D301,E301<=F301),"Oui","Non")) | R301: =IF(B301="","",SUMIFS(PRESENCES_INDEMNITES!$N$2:$N$501,PRESENCES_INDEMNITES!$B$2:$B$501,B301,PRESENCES_INDEMNITES!$S$2:$S$501,"CONFORME")) | S301: =IF(B301="","",SUMIFS(REFERENTIEL_BUDGET!$J$2:$J$101,REFERENTIEL_BUDGET!$A$2:$A$101,B301,REFERENTIEL_BUDGET!$E$2:$E$101,"Indemnités participants")) | T301: =IF(B301="","",IF(COUNTIFS(PRESENCES_INDEMNITES!$B$2:$B$501,B301,PRESENCES_INDEMNITES!$S$2:$S$501,"<>CONFORME",PRESENCES_INDEMNITES!$S$2:$S$501,"<>")>0,"Anomalie détectée",IF(R301>S301,"Dépassement budget indemnités","Conforme"))) | V301: =IF(O301="Non","PJ non reçue",IF(O301="","",IF(Q301="Non","Date PJ non conforme",IF(OR(M301>0,N301<>0,P301="Non",T301="Anomalie détectée",T301="Dépassement budget indemnités"),"Non conforme",IF(P301="À vérifier","À vérifier","Conforme")))))

Sheet PRESENCES_INDEMNITES
A1: N° | B1: Code activité | C1: Participant | D1: Fonction / Structure | E1: Date activité | F1: Présence | G1: Présence2 | H1: Présence3 | I1: Présence4 | J1: Présence5 | K1: Signature / preuve | L1: Taux journalier prévu (Ar) | M1: Indemnité théorique (Ar) | N1: Indemnité reçue (Ar) | O1: Écart indemnité (Ar) | P1: Date dans période ? | Q1: Présence justifie paiement ? | R1: Montant conforme ? | S1: Résultat contrôle | T1: Observation
A2: =ROW()-1 -> 1 | B2: PSN N°1 | C2: KJDSJID | E2: 46153 | F2: Présent | G2: Présent | H2: Présent | I2: Présent | J2: Présent | K2: oui | L2: 150000 | M2: =+COUNTIF(F2:J2,"Présent")*L2 -> 750000 | N2: 750000 | O2: =IF(OR(M2="",N2=""),"",N2-M2) -> 0 | P2: =IF(OR(B2="",E2=""),"",IF(AND(E2>=IFERROR(INDEX(REFERENTIEL_BUDGET!$C$2:$C$101,MATCH(B2,REFERENTIEL_BUDGET!$A$2:$A$101,0)),""),E2<=IFERROR(INDEX(REFERENTIEL_BUDGET!$D$2:$D$101,MATCH(B2,REFERENTIEL_BUDGET!$A$2:$A$101,0)),"")),"Oui","Non")) -> Oui | Q2: =IF(J2="","",IF(AND(J2="Présent",K2<>""),"Oui",IF(J2="Absent","Non","À vérifier"))) -> Oui | R2: =IF(OR(M2="",N2=""),"",IF(O2=0,"Oui","Non")) -> Oui | S2: =IF(B2="","",IF(P2="Non","DATE HORS PÉRIODE",IF(Q2="Non","PAIEMENT SANS PRÉSENCE",IF(Q2="À vérifier","PRÉSENCE À VÉRIFIER",IF(R2="Non","MONTANT NON CONFORME","CONFORME"))))) -> CONFORME
A3: =ROW()-1 -> 2 | B3: PSN N°1 | C3: N CWX SDK | E3: 46153 | F3: Présent | G3: Présent | H3: Présent | I3: Présent | J3: Présent | K3: Non | L3: 150000 | M3: =+COUNTIF(F3:J3,"Présent")*L3 -> 750000 | N3: 750000 | O3: =IF(OR(M3="",N3=""),"",N3-M3) -> 0 | P3: =IF(OR(B3="",E3=""),"",IF(AND(E3>=IFERROR(INDEX(REFERENTIEL_BUDGET!$C$2:$C$101,MATCH(B3,REFERENTIEL_BUDGET!$A$2:$A$101,0)),""),E3<=IFERROR(INDEX(REFERENTIEL_BUDGET!$D$2:$D$101,MATCH(B3,REFERENTIEL_BUDGET!$A$2:$A$101,0)),"")),"Oui","Non")) -> Oui | Q3: =IF(J3="","",IF(AND(J3="Présent",K3<>""),"Oui",IF(J3="Absent","Non","À vérifier"))) -> Oui | R3: =IF(OR(M3="",N3=""),"",IF(O3=0,"Oui","Non")) -> Oui | S3: =IF(B3="","",IF(P3="Non","DATE HORS PÉRIODE",IF(Q3="Non","PAIEMENT SANS PRÉSENCE",IF(Q3="À vérifier","PRÉSENCE À VÉRIFIER",IF(R3="Non","MONTANT NON CONFORME","CONFORME"))))) -> CONFORME
A4: =ROW()-1 -> 3 | B4: PSN N°1 | C4: CBWCB | E4: 46153 | F4: Présent | G4: Présent | H4: Présent | I4: Présent | J4: Présent | K4: oui | L4: 150000 | M4: =+COUNTIF(F4:J4,"Présent")*L4 -> 750000 | N4: 750000 | O4: =IF(OR(M4="",N4=""),"",N4-M4) -> 0 | P4: =IF(OR(B4="",E4=""),"",IF(AND(E4>=IFERROR(INDEX(REFERENTIEL_BUDGET!$C$2:$C$101,MATCH(B4,REFERENTIEL_BUDGET!$A$2:$A$101,0)),""),E4<=IFERROR(INDEX(REFERENTIEL_BUDGET!$D$2:$D$101,MATCH(B4,REFERENTIEL_BUDGET!$A$2:$A$101,0)),"")),"Oui","Non")) -> Oui | Q4: =IF(J4="","",IF(AND(J4="Présent",K4<>""),"Oui",IF(J4="Absent","Non","À vérifier"))) -> Oui | R4: =IF(OR(M4="",N4=""),"",IF(O4=0,"Oui","Non")) -> Oui | S4: =IF(B4="","",IF(P4="Non","DATE HORS PÉRIODE",IF(Q4="Non","PAIEMENT SANS PRÉSENCE",IF(Q4="À vérifier","PRÉSENCE À VÉRIFIER",IF(R4="Non","MONTANT NON CONFORME","CONFORME"))))) -> CONFORME
A5: =ROW()-1 -> 4 | B5: PSN N°1 | C5: CBC XBWSDD | E5: 46153 | F5: Présent | G5: Présent | H5: Présent | I5: Présent | J5: Présent | K5: oui | L5: 150000 | M5: =+COUNTIF(F5:J5,"Présent")*L5 -> 750000 | N5: 750000 | O5: =IF(OR(M5="",N5=""),"",N5-M5) -> 0 | P5: =IF(OR(B5="",E5=""),"",IF(AND(E5>=IFERROR(INDEX(REFERENTIEL_BUDGET!$C$2:$C$101,MATCH(B5,REFERENTIEL_BUDGET!$A$2:$A$101,0)),""),E5<=IFERROR(INDEX(REFERENTIEL_BUDGET!$D$2:$D$101,MATCH(B5,REFERENTIEL_BUDGET!$A$2:$A$101,0)),"")),"Oui","Non")) -> Oui | Q5: =IF(J5="","",IF(AND(J5="Présent",K5<>""),"Oui",IF(J5="Absent","Non","À vérifier"))) -> Oui | R5: =IF(OR(M5="",N5=""),"",IF(O5=0,"Oui","Non")) -> Oui | S5: =IF(B5="","",IF(P5="Non","DATE HORS PÉRIODE",IF(Q5="Non","PAIEMENT SANS PRÉSENCE",IF(Q5="À vérifier","PRÉSENCE À VÉRIFIER",IF(R5="Non","MONTANT NON CONFORME","CONFORME"))))) -> CONFORME
A6: =ROW()-1 -> 5 | B6: PSN N°1 | C6: N? NCBWXNBCD | E6: 46153 | F6: Présent | G6: Présent | H6: Présent | I6: Présent | J6: Présent | K6: oui | L6: 150000 | M6: =+COUNTIF(F6:J6,"Présent")*L6 -> 750000 | N6: 750000 | O6: =IF(OR(M6="",N6=""),"",N6-M6) -> 0 | P6: =IF(OR(B6="",E6=""),"",IF(AND(E6>=IFERROR(INDEX(REFERENTIEL_BUDGET!$C$2:$C$101,MATCH(B6,REFERENTIEL_BUDGET!$A$2:$A$101,0)),""),E6<=IFERROR(INDEX(REFERENTIEL_BUDGET!$D$2:$D$101,MATCH(B6,REFERENTIEL_BUDGET!$A$2:$A$101,0)),"")),"Oui","Non")) -> Oui | Q6: =IF(J6="","",IF(AND(J6="Présent",K6<>""),"Oui",IF(J6="Absent","Non","À vérifier"))) -> Oui | R6: =IF(OR(M6="",N6=""),"",IF(O6=0,"Oui","Non")) -> Oui | S6: =IF(B6="","",IF(P6="Non","DATE HORS PÉRIODE",IF(Q6="Non","PAIEMENT SANS PRÉSENCE",IF(Q6="À vérifier","PRÉSENCE À VÉRIFIER",IF(R6="Non","MONTANT NON CONFORME","CONFORME"))))) -> CONFORME
A7: =ROW()-1 -> 6 | B7: PSN N°1 | C7: ?N XCNW DNC | E7: 46153 | F7: Présent | G7: Présent | H7: Présent | I7: Présent | J7: Présent | K7: oui | L7: 150000 | M7: =+COUNTIF(F7:J7,"Présent")*L7 -> 750000 | N7: 750000 | O7: =IF(OR(M7="",N7=""),"",N7-M7) -> 0 | P7: =IF(OR(B7="",E7=""),"",IF(AND(E7>=IFERROR(INDEX(REFERENTIEL_BUDGET!$C$2:$C$101,MATCH(B7,REFERENTIEL_BUDGET!$A$2:$A$101,0)),""),E7<=IFERROR(INDEX(REFERENTIEL_BUDGET!$D$2:$D$101,MATCH(B7,REFERENTIEL_BUDGET!$A$2:$A$101,0)),"")),"Oui","Non")) -> Oui | Q7: =IF(J7="","",IF(AND(J7="Présent",K7<>""),"Oui",IF(J7="Absent","Non","À vérifier"))) -> Oui | R7: =IF(OR(M7="",N7=""),"",IF(O7=0,"Oui","Non")) -> Oui | S7: =IF(B7="","",IF(P7="Non","DATE HORS PÉRIODE",IF(Q7="Non","PAIEMENT SANS PRÉSENCE",IF(Q7="À vérifier","PRÉSENCE À VÉRIFIER",IF(R7="Non","MONTANT NON CONFORME","CONFORME"))))) -> CONFORME
A8: =ROW()-1 -> 7 | B8: PSN N°1 | C8: DC BCHBSDV | E8: 46153 | F8: Présent | G8: Présent | H8: Présent | I8: Présent | J8: Présent | K8: oui | L8: 150000 | M8: =+COUNTIF(F8:J8,"Présent")*L8 -> 750000 | N8: 750000 | O8: =IF(OR(M8="",N8=""),"",N8-M8) -> 0 | P8: =IF(OR(B8="",E8=""),"",IF(AND(E8>=IFERROR(INDEX(REFERENTIEL_BUDGET!$C$2:$C$101,MATCH(B8,REFERENTIEL_BUDGET!$A$2:$A$101,0)),""),E8<=IFERROR(INDEX(REFERENTIEL_BUDGET!$D$2:$D$101,MATCH(B8,REFERENTIEL_BUDGET!$A$2:$A$101,0)),"")),"Oui","Non")) -> Oui | Q8: =IF(J8="","",IF(AND(J8="Présent",K8<>""),"Oui",IF(J8="Absent","Non","À vérifier"))) -> Oui | R8: =IF(OR(M8="",N8=""),"",IF(O8=0,"Oui","Non")) -> Oui | S8: =IF(B8="","",IF(P8="Non","DATE HORS PÉRIODE",IF(Q8="Non","PAIEMENT SANS PRÉSENCE",IF(Q8="À vérifier","PRÉSENCE À VÉRIFIER",IF(R8="Non","MONTANT NON CONFORME","CONFORME"))))) -> CONFORME
A9: =ROW()-1 -> 8 | B9: PSN N°1 | C9: CBC XBWSDD | E9: 46153 | F9: Présent | G9: Absent | H9: Présent | I9: Présent | J9: Présent | K9: oui | L9: 150000 | M9: =+COUNTIF(F9:J9,"Présent")*L9 -> 600000 | N9: 600000 | O9: =IF(OR(M9="",N9=""),"",N9-M9) -> 0 | P9: =IF(OR(B9="",E9=""),"",IF(AND(E9>=IFERROR(INDEX(REFERENTIEL_BUDGET!$C$2:$C$101,MATCH(B9,REFERENTIEL_BUDGET!$A$2:$A$101,0)),""),E9<=IFERROR(INDEX(REFERENTIEL_BUDGET!$D$2:$D$101,MATCH(B9,REFERENTIEL_BUDGET!$A$2:$A$101,0)),"")),"Oui","Non")) -> Oui | Q9: =IF(J9="","",IF(AND(J9="Présent",K9<>""),"Oui",IF(J9="Absent","Non","À vérifier"))) -> Oui | R9: =IF(OR(M9="",N9=""),"",IF(O9=0,"Oui","Non")) -> Oui | S9: =IF(B9="","",IF(P9="Non","DATE HORS PÉRIODE",IF(Q9="Non","PAIEMENT SANS PRÉSENCE",IF(Q9="À vérifier","PRÉSENCE À VÉRIFIER",IF(R9="Non","MONTANT NON CONFORME","CONFORME"))))) -> CONFORME
A10: =ROW()-1 -> 9 | B10: PSN N°1 | C10: N? NCBWXNBCD | E10: 46153 | F10: Présent | G10: Absent | H10: Présent | I10: Présent | J10: Présent | K10: oui | L10: 150000 | M10: =+COUNTIF(F10:J10,"Présent")*L10 -> 600000 | N10: 600000 | O10: =IF(OR(M10="",N10=""),"",N10-M10) -> 0 | P10: =IF(OR(B10="",E10=""),"",IF(AND(E10>=IFERROR(INDEX(REFERENTIEL_BUDGET!$C$2:$C$101,MATCH(B10,REFERENTIEL_BUDGET!$A$2:$A$101,0)),""),E10<=IFERROR(INDEX(REFERENTIEL_BUDGET!$D$2:$D$101,MATCH(B10,REFERENTIEL_BUDGET!$A$2:$A$101,0)),"")),"Oui","Non")) -> Oui | Q10: =IF(J10="","",IF(AND(J10="Présent",K10<>""),"Oui",IF(J10="Absent","Non","À vérifier"))) -> Oui | R10: =IF(OR(M10="",N10=""),"",IF(O10=0,"Oui","Non")) -> Oui | S10: =IF(B10="","",IF(P10="Non","DATE HORS PÉRIODE",IF(Q10="Non","PAIEMENT SANS PRÉSENCE",IF(Q10="À vérifier","PRÉSENCE À VÉRIFIER",IF(R10="Non","MONTANT NON CONFORME","CONFORME"))))) -> CONFORME
